[0m17:18:45.560157 [debug] [MainThread]: Sending event: {'category': 'dbt', 'action': 'invocation', 'label': 'start', 'context': [<snowplow_tracker.self_describing_json.SelfDescribingJson object at 0x0000022F1CAF4A30>, <snowplow_tracker.self_describing_json.SelfDescribingJson object at 0x0000022F1E973730>, <snowplow_tracker.self_describing_json.SelfDescribingJson object at 0x0000022F1E973520>]}


============================== 17:18:45.567173 | 86b45bef-e736-43da-b00c-5f5635ec5c33 ==============================
[0m17:18:45.567173 [info ] [MainThread]: Running with dbt=1.9.1
[0m17:18:45.569174 [debug] [MainThread]: running dbt with arguments {'printer_width': '80', 'indirect_selection': 'eager', 'log_cache_events': 'False', 'write_json': 'True', 'partial_parse': 'True', 'cache_selected_only': 'False', 'profiles_dir': 'C:\\Users\\abhishek.2.kumar\\course\\dbt_demo', 'debug': 'False', 'version_check': 'True', 'log_path': 'C:\\Users\\abhishek.2.kumar\\course\\dbt_demo\\logs', 'fail_fast': 'False', 'warn_error': 'None', 'use_colors': 'True', 'use_experimental_parser': 'False', 'empty': 'None', 'quiet': 'False', 'no_print': 'None', 'warn_error_options': 'WarnErrorOptions(include=[], exclude=[])', 'static_parser': 'True', 'introspect': 'True', 'log_format': 'default', 'target_path': 'None', 'invocation_command': 'dbt clean', 'send_anonymous_usage_stats': 'True'}
[0m17:18:45.818144 [debug] [MainThread]: Sending event: {'category': 'dbt', 'action': 'project_id', 'label': '86b45bef-e736-43da-b00c-5f5635ec5c33', 'context': [<snowplow_tracker.self_describing_json.SelfDescribingJson object at 0x0000022F1E9CB490>]}
[0m17:18:45.905995 [debug] [MainThread]: Command `dbt clean` succeeded at 17:18:45.904655 after 0.46 seconds
[0m17:18:45.907278 [debug] [MainThread]: Sending event: {'category': 'dbt', 'action': 'invocation', 'label': 'end', 'context': [<snowplow_tracker.self_describing_json.SelfDescribingJson object at 0x0000022F1CAF4A30>, <snowplow_tracker.self_describing_json.SelfDescribingJson object at 0x0000022F1E9C8CA0>, <snowplow_tracker.self_describing_json.SelfDescribingJson object at 0x0000022F1E9CA0E0>]}
[0m17:18:45.909972 [debug] [MainThread]: Flushing usage events
[0m17:18:46.321667 [debug] [MainThread]: An error was encountered while trying to flush usage events
[0m17:18:55.135963 [debug] [MainThread]: Sending event: {'category': 'dbt', 'action': 'invocation', 'label': 'start', 'context': [<snowplow_tracker.self_describing_json.SelfDescribingJson object at 0x000002BC9EA14A90>, <snowplow_tracker.self_describing_json.SelfDescribingJson object at 0x000002BCA08E4820>, <snowplow_tracker.self_describing_json.SelfDescribingJson object at 0x000002BCA08E4A30>]}


============================== 17:18:55.139963 | 4fb48da5-9698-424d-95cb-1089d130ad67 ==============================
[0m17:18:55.139963 [info ] [MainThread]: Running with dbt=1.9.1
[0m17:18:55.141966 [debug] [MainThread]: running dbt with arguments {'printer_width': '80', 'indirect_selection': 'eager', 'write_json': 'True', 'log_cache_events': 'False', 'partial_parse': 'True', 'cache_selected_only': 'False', 'profiles_dir': 'C:\\Users\\abhishek.2.kumar\\course\\dbt_demo', 'debug': 'False', 'fail_fast': 'False', 'log_path': 'C:\\Users\\abhishek.2.kumar\\course\\dbt_demo\\logs', 'warn_error': 'None', 'version_check': 'True', 'use_colors': 'True', 'use_experimental_parser': 'False', 'no_print': 'None', 'quiet': 'False', 'empty': 'None', 'warn_error_options': 'WarnErrorOptions(include=[], exclude=[])', 'introspect': 'True', 'invocation_command': 'dbt deps', 'log_format': 'default', 'target_path': 'None', 'static_parser': 'True', 'send_anonymous_usage_stats': 'True'}
[0m17:18:55.335345 [debug] [MainThread]: Sending event: {'category': 'dbt', 'action': 'project_id', 'label': '4fb48da5-9698-424d-95cb-1089d130ad67', 'context': [<snowplow_tracker.self_describing_json.SelfDescribingJson object at 0x000002BCA08E6800>]}
[0m17:18:55.385114 [debug] [MainThread]: Set downloads directory='C:\Users\ABHISH~1.KUM\AppData\Local\Temp\dbt-downloads-3jpv5ber'
[0m17:18:55.385815 [debug] [MainThread]: Making package index registry request: GET https://hub.getdbt.com/api/v1/index.json
[0m17:18:55.879503 [debug] [MainThread]: External call exception: HTTPSConnectionPool(host='hub.getdbt.com', port=443): Max retries exceeded with url: /api/v1/index.json (Caused by SSLError(SSLCertVerificationError(1, '[SSL: CERTIFICATE_VERIFY_FAILED] certificate verify failed: unable to get local issuer certificate (_ssl.c:997)')))
[0m17:18:55.880505 [debug] [MainThread]: Retrying external call. Attempt: 0 Max attempts: 5
[0m17:18:56.881098 [debug] [MainThread]: Making package index registry request: GET https://hub.getdbt.com/api/v1/index.json
[0m17:18:57.239472 [debug] [MainThread]: External call exception: HTTPSConnectionPool(host='hub.getdbt.com', port=443): Max retries exceeded with url: /api/v1/index.json (Caused by SSLError(SSLCertVerificationError(1, '[SSL: CERTIFICATE_VERIFY_FAILED] certificate verify failed: unable to get local issuer certificate (_ssl.c:997)')))
[0m17:18:57.239472 [debug] [MainThread]: Retrying external call. Attempt: 1 Max attempts: 5
[0m17:18:58.242232 [debug] [MainThread]: Making package index registry request: GET https://hub.getdbt.com/api/v1/index.json
[0m17:18:58.552583 [debug] [MainThread]: External call exception: HTTPSConnectionPool(host='hub.getdbt.com', port=443): Max retries exceeded with url: /api/v1/index.json (Caused by SSLError(SSLCertVerificationError(1, '[SSL: CERTIFICATE_VERIFY_FAILED] certificate verify failed: unable to get local issuer certificate (_ssl.c:997)')))
[0m17:18:58.553582 [debug] [MainThread]: Retrying external call. Attempt: 2 Max attempts: 5
[0m17:18:59.555427 [debug] [MainThread]: Making package index registry request: GET https://hub.getdbt.com/api/v1/index.json
[0m17:18:59.866376 [debug] [MainThread]: External call exception: HTTPSConnectionPool(host='hub.getdbt.com', port=443): Max retries exceeded with url: /api/v1/index.json (Caused by SSLError(SSLCertVerificationError(1, '[SSL: CERTIFICATE_VERIFY_FAILED] certificate verify failed: unable to get local issuer certificate (_ssl.c:997)')))
[0m17:18:59.867375 [debug] [MainThread]: Retrying external call. Attempt: 3 Max attempts: 5
[0m17:19:00.868568 [debug] [MainThread]: Making package index registry request: GET https://hub.getdbt.com/api/v1/index.json
[0m17:19:01.431764 [debug] [MainThread]: External call exception: HTTPSConnectionPool(host='hub.getdbt.com', port=443): Max retries exceeded with url: /api/v1/index.json (Caused by SSLError(SSLCertVerificationError(1, '[SSL: CERTIFICATE_VERIFY_FAILED] certificate verify failed: unable to get local issuer certificate (_ssl.c:997)')))
[0m17:19:01.432762 [debug] [MainThread]: Retrying external call. Attempt: 4 Max attempts: 5
[0m17:19:02.434135 [debug] [MainThread]: Making package index registry request: GET https://hub.getdbt.com/api/v1/index.json
[0m17:19:02.805827 [error] [MainThread]: Encountered an error:
External connection exception occurred: HTTPSConnectionPool(host='hub.getdbt.com', port=443): Max retries exceeded with url: /api/v1/index.json (Caused by SSLError(SSLCertVerificationError(1, '[SSL: CERTIFICATE_VERIFY_FAILED] certificate verify failed: unable to get local issuer certificate (_ssl.c:997)')))
[0m17:19:02.825962 [error] [MainThread]: Traceback (most recent call last):
  File "C:\Users\abhishek.2.kumar\course\venv\lib\site-packages\urllib3\connectionpool.py", line 464, in _make_request
    self._validate_conn(conn)
  File "C:\Users\abhishek.2.kumar\course\venv\lib\site-packages\urllib3\connectionpool.py", line 1093, in _validate_conn
    conn.connect()
  File "C:\Users\abhishek.2.kumar\course\venv\lib\site-packages\urllib3\connection.py", line 741, in connect
    sock_and_verified = _ssl_wrap_socket_and_match_hostname(
  File "C:\Users\abhishek.2.kumar\course\venv\lib\site-packages\urllib3\connection.py", line 920, in _ssl_wrap_socket_and_match_hostname
    ssl_sock = ssl_wrap_socket(
  File "C:\Users\abhishek.2.kumar\course\venv\lib\site-packages\urllib3\util\ssl_.py", line 460, in ssl_wrap_socket
    ssl_sock = _ssl_wrap_socket_impl(sock, context, tls_in_tls, server_hostname)
  File "C:\Users\abhishek.2.kumar\course\venv\lib\site-packages\urllib3\util\ssl_.py", line 504, in _ssl_wrap_socket_impl
    return ssl_context.wrap_socket(sock, server_hostname=server_hostname)
  File "C:\Users\abhishek.2.kumar\AppData\Local\Programs\Python\Python310\lib\ssl.py", line 513, in wrap_socket
    return self.sslsocket_class._create(
  File "C:\Users\abhishek.2.kumar\AppData\Local\Programs\Python\Python310\lib\ssl.py", line 1071, in _create
    self.do_handshake()
  File "C:\Users\abhishek.2.kumar\AppData\Local\Programs\Python\Python310\lib\ssl.py", line 1342, in do_handshake
    self._sslobj.do_handshake()
ssl.SSLCertVerificationError: [SSL: CERTIFICATE_VERIFY_FAILED] certificate verify failed: unable to get local issuer certificate (_ssl.c:997)

During handling of the above exception, another exception occurred:

Traceback (most recent call last):
  File "C:\Users\abhishek.2.kumar\course\venv\lib\site-packages\urllib3\connectionpool.py", line 787, in urlopen
    response = self._make_request(
  File "C:\Users\abhishek.2.kumar\course\venv\lib\site-packages\urllib3\connectionpool.py", line 488, in _make_request
    raise new_e
urllib3.exceptions.SSLError: [SSL: CERTIFICATE_VERIFY_FAILED] certificate verify failed: unable to get local issuer certificate (_ssl.c:997)

The above exception was the direct cause of the following exception:

Traceback (most recent call last):
  File "C:\Users\abhishek.2.kumar\course\venv\lib\site-packages\requests\adapters.py", line 667, in send
    resp = conn.urlopen(
  File "C:\Users\abhishek.2.kumar\course\venv\lib\site-packages\urllib3\connectionpool.py", line 841, in urlopen
    retries = retries.increment(
  File "C:\Users\abhishek.2.kumar\course\venv\lib\site-packages\urllib3\util\retry.py", line 519, in increment
    raise MaxRetryError(_pool, url, reason) from reason  # type: ignore[arg-type]
urllib3.exceptions.MaxRetryError: HTTPSConnectionPool(host='hub.getdbt.com', port=443): Max retries exceeded with url: /api/v1/index.json (Caused by SSLError(SSLCertVerificationError(1, '[SSL: CERTIFICATE_VERIFY_FAILED] certificate verify failed: unable to get local issuer certificate (_ssl.c:997)')))

During handling of the above exception, another exception occurred:

Traceback (most recent call last):
  File "C:\Users\abhishek.2.kumar\course\venv\lib\site-packages\dbt_common\utils\connection.py", line 21, in connection_exception_retry
    return fn()
  File "C:\Users\abhishek.2.kumar\course\venv\lib\site-packages\dbt\clients\registry.py", line 168, in _get_index
    resp = requests.get(url, timeout=30)
  File "C:\Users\abhishek.2.kumar\course\venv\lib\site-packages\requests\api.py", line 73, in get
    return request("get", url, params=params, **kwargs)
  File "C:\Users\abhishek.2.kumar\course\venv\lib\site-packages\requests\api.py", line 59, in request
    return session.request(method=method, url=url, **kwargs)
  File "C:\Users\abhishek.2.kumar\course\venv\lib\site-packages\requests\sessions.py", line 589, in request
    resp = self.send(prep, **send_kwargs)
  File "C:\Users\abhishek.2.kumar\course\venv\lib\site-packages\requests\sessions.py", line 703, in send
    r = adapter.send(request, **kwargs)
  File "C:\Users\abhishek.2.kumar\course\venv\lib\site-packages\requests\adapters.py", line 698, in send
    raise SSLError(e, request=request)
requests.exceptions.SSLError: HTTPSConnectionPool(host='hub.getdbt.com', port=443): Max retries exceeded with url: /api/v1/index.json (Caused by SSLError(SSLCertVerificationError(1, '[SSL: CERTIFICATE_VERIFY_FAILED] certificate verify failed: unable to get local issuer certificate (_ssl.c:997)')))

During handling of the above exception, another exception occurred:

Traceback (most recent call last):
  File "C:\Users\abhishek.2.kumar\course\venv\lib\site-packages\urllib3\connectionpool.py", line 464, in _make_request
    self._validate_conn(conn)
  File "C:\Users\abhishek.2.kumar\course\venv\lib\site-packages\urllib3\connectionpool.py", line 1093, in _validate_conn
    conn.connect()
  File "C:\Users\abhishek.2.kumar\course\venv\lib\site-packages\urllib3\connection.py", line 741, in connect
    sock_and_verified = _ssl_wrap_socket_and_match_hostname(
  File "C:\Users\abhishek.2.kumar\course\venv\lib\site-packages\urllib3\connection.py", line 920, in _ssl_wrap_socket_and_match_hostname
    ssl_sock = ssl_wrap_socket(
  File "C:\Users\abhishek.2.kumar\course\venv\lib\site-packages\urllib3\util\ssl_.py", line 460, in ssl_wrap_socket
    ssl_sock = _ssl_wrap_socket_impl(sock, context, tls_in_tls, server_hostname)
  File "C:\Users\abhishek.2.kumar\course\venv\lib\site-packages\urllib3\util\ssl_.py", line 504, in _ssl_wrap_socket_impl
    return ssl_context.wrap_socket(sock, server_hostname=server_hostname)
  File "C:\Users\abhishek.2.kumar\AppData\Local\Programs\Python\Python310\lib\ssl.py", line 513, in wrap_socket
    return self.sslsocket_class._create(
  File "C:\Users\abhishek.2.kumar\AppData\Local\Programs\Python\Python310\lib\ssl.py", line 1071, in _create
    self.do_handshake()
  File "C:\Users\abhishek.2.kumar\AppData\Local\Programs\Python\Python310\lib\ssl.py", line 1342, in do_handshake
    self._sslobj.do_handshake()
ssl.SSLCertVerificationError: [SSL: CERTIFICATE_VERIFY_FAILED] certificate verify failed: unable to get local issuer certificate (_ssl.c:997)

During handling of the above exception, another exception occurred:

Traceback (most recent call last):
  File "C:\Users\abhishek.2.kumar\course\venv\lib\site-packages\urllib3\connectionpool.py", line 787, in urlopen
    response = self._make_request(
  File "C:\Users\abhishek.2.kumar\course\venv\lib\site-packages\urllib3\connectionpool.py", line 488, in _make_request
    raise new_e
urllib3.exceptions.SSLError: [SSL: CERTIFICATE_VERIFY_FAILED] certificate verify failed: unable to get local issuer certificate (_ssl.c:997)

The above exception was the direct cause of the following exception:

Traceback (most recent call last):
  File "C:\Users\abhishek.2.kumar\course\venv\lib\site-packages\requests\adapters.py", line 667, in send
    resp = conn.urlopen(
  File "C:\Users\abhishek.2.kumar\course\venv\lib\site-packages\urllib3\connectionpool.py", line 841, in urlopen
    retries = retries.increment(
  File "C:\Users\abhishek.2.kumar\course\venv\lib\site-packages\urllib3\util\retry.py", line 519, in increment
    raise MaxRetryError(_pool, url, reason) from reason  # type: ignore[arg-type]
urllib3.exceptions.MaxRetryError: HTTPSConnectionPool(host='hub.getdbt.com', port=443): Max retries exceeded with url: /api/v1/index.json (Caused by SSLError(SSLCertVerificationError(1, '[SSL: CERTIFICATE_VERIFY_FAILED] certificate verify failed: unable to get local issuer certificate (_ssl.c:997)')))

During handling of the above exception, another exception occurred:

Traceback (most recent call last):
  File "C:\Users\abhishek.2.kumar\course\venv\lib\site-packages\dbt_common\utils\connection.py", line 21, in connection_exception_retry
    return fn()
  File "C:\Users\abhishek.2.kumar\course\venv\lib\site-packages\dbt\clients\registry.py", line 168, in _get_index
    resp = requests.get(url, timeout=30)
  File "C:\Users\abhishek.2.kumar\course\venv\lib\site-packages\requests\api.py", line 73, in get
    return request("get", url, params=params, **kwargs)
  File "C:\Users\abhishek.2.kumar\course\venv\lib\site-packages\requests\api.py", line 59, in request
    return session.request(method=method, url=url, **kwargs)
  File "C:\Users\abhishek.2.kumar\course\venv\lib\site-packages\requests\sessions.py", line 589, in request
    resp = self.send(prep, **send_kwargs)
  File "C:\Users\abhishek.2.kumar\course\venv\lib\site-packages\requests\sessions.py", line 703, in send
    r = adapter.send(request, **kwargs)
  File "C:\Users\abhishek.2.kumar\course\venv\lib\site-packages\requests\adapters.py", line 698, in send
    raise SSLError(e, request=request)
requests.exceptions.SSLError: HTTPSConnectionPool(host='hub.getdbt.com', port=443): Max retries exceeded with url: /api/v1/index.json (Caused by SSLError(SSLCertVerificationError(1, '[SSL: CERTIFICATE_VERIFY_FAILED] certificate verify failed: unable to get local issuer certificate (_ssl.c:997)')))

During handling of the above exception, another exception occurred:

Traceback (most recent call last):
  File "C:\Users\abhishek.2.kumar\course\venv\lib\site-packages\urllib3\connectionpool.py", line 464, in _make_request
    self._validate_conn(conn)
  File "C:\Users\abhishek.2.kumar\course\venv\lib\site-packages\urllib3\connectionpool.py", line 1093, in _validate_conn
    conn.connect()
  File "C:\Users\abhishek.2.kumar\course\venv\lib\site-packages\urllib3\connection.py", line 741, in connect
    sock_and_verified = _ssl_wrap_socket_and_match_hostname(
  File "C:\Users\abhishek.2.kumar\course\venv\lib\site-packages\urllib3\connection.py", line 920, in _ssl_wrap_socket_and_match_hostname
    ssl_sock = ssl_wrap_socket(
  File "C:\Users\abhishek.2.kumar\course\venv\lib\site-packages\urllib3\util\ssl_.py", line 460, in ssl_wrap_socket
    ssl_sock = _ssl_wrap_socket_impl(sock, context, tls_in_tls, server_hostname)
  File "C:\Users\abhishek.2.kumar\course\venv\lib\site-packages\urllib3\util\ssl_.py", line 504, in _ssl_wrap_socket_impl
    return ssl_context.wrap_socket(sock, server_hostname=server_hostname)
  File "C:\Users\abhishek.2.kumar\AppData\Local\Programs\Python\Python310\lib\ssl.py", line 513, in wrap_socket
    return self.sslsocket_class._create(
  File "C:\Users\abhishek.2.kumar\AppData\Local\Programs\Python\Python310\lib\ssl.py", line 1071, in _create
    self.do_handshake()
  File "C:\Users\abhishek.2.kumar\AppData\Local\Programs\Python\Python310\lib\ssl.py", line 1342, in do_handshake
    self._sslobj.do_handshake()
ssl.SSLCertVerificationError: [SSL: CERTIFICATE_VERIFY_FAILED] certificate verify failed: unable to get local issuer certificate (_ssl.c:997)

During handling of the above exception, another exception occurred:

Traceback (most recent call last):
  File "C:\Users\abhishek.2.kumar\course\venv\lib\site-packages\urllib3\connectionpool.py", line 787, in urlopen
    response = self._make_request(
  File "C:\Users\abhishek.2.kumar\course\venv\lib\site-packages\urllib3\connectionpool.py", line 488, in _make_request
    raise new_e
urllib3.exceptions.SSLError: [SSL: CERTIFICATE_VERIFY_FAILED] certificate verify failed: unable to get local issuer certificate (_ssl.c:997)

The above exception was the direct cause of the following exception:

Traceback (most recent call last):
  File "C:\Users\abhishek.2.kumar\course\venv\lib\site-packages\requests\adapters.py", line 667, in send
    resp = conn.urlopen(
  File "C:\Users\abhishek.2.kumar\course\venv\lib\site-packages\urllib3\connectionpool.py", line 841, in urlopen
    retries = retries.increment(
  File "C:\Users\abhishek.2.kumar\course\venv\lib\site-packages\urllib3\util\retry.py", line 519, in increment
    raise MaxRetryError(_pool, url, reason) from reason  # type: ignore[arg-type]
urllib3.exceptions.MaxRetryError: HTTPSConnectionPool(host='hub.getdbt.com', port=443): Max retries exceeded with url: /api/v1/index.json (Caused by SSLError(SSLCertVerificationError(1, '[SSL: CERTIFICATE_VERIFY_FAILED] certificate verify failed: unable to get local issuer certificate (_ssl.c:997)')))

During handling of the above exception, another exception occurred:

Traceback (most recent call last):
  File "C:\Users\abhishek.2.kumar\course\venv\lib\site-packages\dbt_common\utils\connection.py", line 21, in connection_exception_retry
    return fn()
  File "C:\Users\abhishek.2.kumar\course\venv\lib\site-packages\dbt\clients\registry.py", line 168, in _get_index
    resp = requests.get(url, timeout=30)
  File "C:\Users\abhishek.2.kumar\course\venv\lib\site-packages\requests\api.py", line 73, in get
    return request("get", url, params=params, **kwargs)
  File "C:\Users\abhishek.2.kumar\course\venv\lib\site-packages\requests\api.py", line 59, in request
    return session.request(method=method, url=url, **kwargs)
  File "C:\Users\abhishek.2.kumar\course\venv\lib\site-packages\requests\sessions.py", line 589, in request
    resp = self.send(prep, **send_kwargs)
  File "C:\Users\abhishek.2.kumar\course\venv\lib\site-packages\requests\sessions.py", line 703, in send
    r = adapter.send(request, **kwargs)
  File "C:\Users\abhishek.2.kumar\course\venv\lib\site-packages\requests\adapters.py", line 698, in send
    raise SSLError(e, request=request)
requests.exceptions.SSLError: HTTPSConnectionPool(host='hub.getdbt.com', port=443): Max retries exceeded with url: /api/v1/index.json (Caused by SSLError(SSLCertVerificationError(1, '[SSL: CERTIFICATE_VERIFY_FAILED] certificate verify failed: unable to get local issuer certificate (_ssl.c:997)')))

During handling of the above exception, another exception occurred:

Traceback (most recent call last):
  File "C:\Users\abhishek.2.kumar\course\venv\lib\site-packages\urllib3\connectionpool.py", line 464, in _make_request
    self._validate_conn(conn)
  File "C:\Users\abhishek.2.kumar\course\venv\lib\site-packages\urllib3\connectionpool.py", line 1093, in _validate_conn
    conn.connect()
  File "C:\Users\abhishek.2.kumar\course\venv\lib\site-packages\urllib3\connection.py", line 741, in connect
    sock_and_verified = _ssl_wrap_socket_and_match_hostname(
  File "C:\Users\abhishek.2.kumar\course\venv\lib\site-packages\urllib3\connection.py", line 920, in _ssl_wrap_socket_and_match_hostname
    ssl_sock = ssl_wrap_socket(
  File "C:\Users\abhishek.2.kumar\course\venv\lib\site-packages\urllib3\util\ssl_.py", line 460, in ssl_wrap_socket
    ssl_sock = _ssl_wrap_socket_impl(sock, context, tls_in_tls, server_hostname)
  File "C:\Users\abhishek.2.kumar\course\venv\lib\site-packages\urllib3\util\ssl_.py", line 504, in _ssl_wrap_socket_impl
    return ssl_context.wrap_socket(sock, server_hostname=server_hostname)
  File "C:\Users\abhishek.2.kumar\AppData\Local\Programs\Python\Python310\lib\ssl.py", line 513, in wrap_socket
    return self.sslsocket_class._create(
  File "C:\Users\abhishek.2.kumar\AppData\Local\Programs\Python\Python310\lib\ssl.py", line 1071, in _create
    self.do_handshake()
  File "C:\Users\abhishek.2.kumar\AppData\Local\Programs\Python\Python310\lib\ssl.py", line 1342, in do_handshake
    self._sslobj.do_handshake()
ssl.SSLCertVerificationError: [SSL: CERTIFICATE_VERIFY_FAILED] certificate verify failed: unable to get local issuer certificate (_ssl.c:997)

During handling of the above exception, another exception occurred:

Traceback (most recent call last):
  File "C:\Users\abhishek.2.kumar\course\venv\lib\site-packages\urllib3\connectionpool.py", line 787, in urlopen
    response = self._make_request(
  File "C:\Users\abhishek.2.kumar\course\venv\lib\site-packages\urllib3\connectionpool.py", line 488, in _make_request
    raise new_e
urllib3.exceptions.SSLError: [SSL: CERTIFICATE_VERIFY_FAILED] certificate verify failed: unable to get local issuer certificate (_ssl.c:997)

The above exception was the direct cause of the following exception:

Traceback (most recent call last):
  File "C:\Users\abhishek.2.kumar\course\venv\lib\site-packages\requests\adapters.py", line 667, in send
    resp = conn.urlopen(
  File "C:\Users\abhishek.2.kumar\course\venv\lib\site-packages\urllib3\connectionpool.py", line 841, in urlopen
    retries = retries.increment(
  File "C:\Users\abhishek.2.kumar\course\venv\lib\site-packages\urllib3\util\retry.py", line 519, in increment
    raise MaxRetryError(_pool, url, reason) from reason  # type: ignore[arg-type]
urllib3.exceptions.MaxRetryError: HTTPSConnectionPool(host='hub.getdbt.com', port=443): Max retries exceeded with url: /api/v1/index.json (Caused by SSLError(SSLCertVerificationError(1, '[SSL: CERTIFICATE_VERIFY_FAILED] certificate verify failed: unable to get local issuer certificate (_ssl.c:997)')))

During handling of the above exception, another exception occurred:

Traceback (most recent call last):
  File "C:\Users\abhishek.2.kumar\course\venv\lib\site-packages\dbt_common\utils\connection.py", line 21, in connection_exception_retry
    return fn()
  File "C:\Users\abhishek.2.kumar\course\venv\lib\site-packages\dbt\clients\registry.py", line 168, in _get_index
    resp = requests.get(url, timeout=30)
  File "C:\Users\abhishek.2.kumar\course\venv\lib\site-packages\requests\api.py", line 73, in get
    return request("get", url, params=params, **kwargs)
  File "C:\Users\abhishek.2.kumar\course\venv\lib\site-packages\requests\api.py", line 59, in request
    return session.request(method=method, url=url, **kwargs)
  File "C:\Users\abhishek.2.kumar\course\venv\lib\site-packages\requests\sessions.py", line 589, in request
    resp = self.send(prep, **send_kwargs)
  File "C:\Users\abhishek.2.kumar\course\venv\lib\site-packages\requests\sessions.py", line 703, in send
    r = adapter.send(request, **kwargs)
  File "C:\Users\abhishek.2.kumar\course\venv\lib\site-packages\requests\adapters.py", line 698, in send
    raise SSLError(e, request=request)
requests.exceptions.SSLError: HTTPSConnectionPool(host='hub.getdbt.com', port=443): Max retries exceeded with url: /api/v1/index.json (Caused by SSLError(SSLCertVerificationError(1, '[SSL: CERTIFICATE_VERIFY_FAILED] certificate verify failed: unable to get local issuer certificate (_ssl.c:997)')))

During handling of the above exception, another exception occurred:

Traceback (most recent call last):
  File "C:\Users\abhishek.2.kumar\course\venv\lib\site-packages\urllib3\connectionpool.py", line 464, in _make_request
    self._validate_conn(conn)
  File "C:\Users\abhishek.2.kumar\course\venv\lib\site-packages\urllib3\connectionpool.py", line 1093, in _validate_conn
    conn.connect()
  File "C:\Users\abhishek.2.kumar\course\venv\lib\site-packages\urllib3\connection.py", line 741, in connect
    sock_and_verified = _ssl_wrap_socket_and_match_hostname(
  File "C:\Users\abhishek.2.kumar\course\venv\lib\site-packages\urllib3\connection.py", line 920, in _ssl_wrap_socket_and_match_hostname
    ssl_sock = ssl_wrap_socket(
  File "C:\Users\abhishek.2.kumar\course\venv\lib\site-packages\urllib3\util\ssl_.py", line 460, in ssl_wrap_socket
    ssl_sock = _ssl_wrap_socket_impl(sock, context, tls_in_tls, server_hostname)
  File "C:\Users\abhishek.2.kumar\course\venv\lib\site-packages\urllib3\util\ssl_.py", line 504, in _ssl_wrap_socket_impl
    return ssl_context.wrap_socket(sock, server_hostname=server_hostname)
  File "C:\Users\abhishek.2.kumar\AppData\Local\Programs\Python\Python310\lib\ssl.py", line 513, in wrap_socket
    return self.sslsocket_class._create(
  File "C:\Users\abhishek.2.kumar\AppData\Local\Programs\Python\Python310\lib\ssl.py", line 1071, in _create
    self.do_handshake()
  File "C:\Users\abhishek.2.kumar\AppData\Local\Programs\Python\Python310\lib\ssl.py", line 1342, in do_handshake
    self._sslobj.do_handshake()
ssl.SSLCertVerificationError: [SSL: CERTIFICATE_VERIFY_FAILED] certificate verify failed: unable to get local issuer certificate (_ssl.c:997)

During handling of the above exception, another exception occurred:

Traceback (most recent call last):
  File "C:\Users\abhishek.2.kumar\course\venv\lib\site-packages\urllib3\connectionpool.py", line 787, in urlopen
    response = self._make_request(
  File "C:\Users\abhishek.2.kumar\course\venv\lib\site-packages\urllib3\connectionpool.py", line 488, in _make_request
    raise new_e
urllib3.exceptions.SSLError: [SSL: CERTIFICATE_VERIFY_FAILED] certificate verify failed: unable to get local issuer certificate (_ssl.c:997)

The above exception was the direct cause of the following exception:

Traceback (most recent call last):
  File "C:\Users\abhishek.2.kumar\course\venv\lib\site-packages\requests\adapters.py", line 667, in send
    resp = conn.urlopen(
  File "C:\Users\abhishek.2.kumar\course\venv\lib\site-packages\urllib3\connectionpool.py", line 841, in urlopen
    retries = retries.increment(
  File "C:\Users\abhishek.2.kumar\course\venv\lib\site-packages\urllib3\util\retry.py", line 519, in increment
    raise MaxRetryError(_pool, url, reason) from reason  # type: ignore[arg-type]
urllib3.exceptions.MaxRetryError: HTTPSConnectionPool(host='hub.getdbt.com', port=443): Max retries exceeded with url: /api/v1/index.json (Caused by SSLError(SSLCertVerificationError(1, '[SSL: CERTIFICATE_VERIFY_FAILED] certificate verify failed: unable to get local issuer certificate (_ssl.c:997)')))

During handling of the above exception, another exception occurred:

Traceback (most recent call last):
  File "C:\Users\abhishek.2.kumar\course\venv\lib\site-packages\dbt_common\utils\connection.py", line 21, in connection_exception_retry
    return fn()
  File "C:\Users\abhishek.2.kumar\course\venv\lib\site-packages\dbt\clients\registry.py", line 168, in _get_index
    resp = requests.get(url, timeout=30)
  File "C:\Users\abhishek.2.kumar\course\venv\lib\site-packages\requests\api.py", line 73, in get
    return request("get", url, params=params, **kwargs)
  File "C:\Users\abhishek.2.kumar\course\venv\lib\site-packages\requests\api.py", line 59, in request
    return session.request(method=method, url=url, **kwargs)
  File "C:\Users\abhishek.2.kumar\course\venv\lib\site-packages\requests\sessions.py", line 589, in request
    resp = self.send(prep, **send_kwargs)
  File "C:\Users\abhishek.2.kumar\course\venv\lib\site-packages\requests\sessions.py", line 703, in send
    r = adapter.send(request, **kwargs)
  File "C:\Users\abhishek.2.kumar\course\venv\lib\site-packages\requests\adapters.py", line 698, in send
    raise SSLError(e, request=request)
requests.exceptions.SSLError: HTTPSConnectionPool(host='hub.getdbt.com', port=443): Max retries exceeded with url: /api/v1/index.json (Caused by SSLError(SSLCertVerificationError(1, '[SSL: CERTIFICATE_VERIFY_FAILED] certificate verify failed: unable to get local issuer certificate (_ssl.c:997)')))

During handling of the above exception, another exception occurred:

Traceback (most recent call last):
  File "C:\Users\abhishek.2.kumar\course\venv\lib\site-packages\urllib3\connectionpool.py", line 464, in _make_request
    self._validate_conn(conn)
  File "C:\Users\abhishek.2.kumar\course\venv\lib\site-packages\urllib3\connectionpool.py", line 1093, in _validate_conn
    conn.connect()
  File "C:\Users\abhishek.2.kumar\course\venv\lib\site-packages\urllib3\connection.py", line 741, in connect
    sock_and_verified = _ssl_wrap_socket_and_match_hostname(
  File "C:\Users\abhishek.2.kumar\course\venv\lib\site-packages\urllib3\connection.py", line 920, in _ssl_wrap_socket_and_match_hostname
    ssl_sock = ssl_wrap_socket(
  File "C:\Users\abhishek.2.kumar\course\venv\lib\site-packages\urllib3\util\ssl_.py", line 460, in ssl_wrap_socket
    ssl_sock = _ssl_wrap_socket_impl(sock, context, tls_in_tls, server_hostname)
  File "C:\Users\abhishek.2.kumar\course\venv\lib\site-packages\urllib3\util\ssl_.py", line 504, in _ssl_wrap_socket_impl
    return ssl_context.wrap_socket(sock, server_hostname=server_hostname)
  File "C:\Users\abhishek.2.kumar\AppData\Local\Programs\Python\Python310\lib\ssl.py", line 513, in wrap_socket
    return self.sslsocket_class._create(
  File "C:\Users\abhishek.2.kumar\AppData\Local\Programs\Python\Python310\lib\ssl.py", line 1071, in _create
    self.do_handshake()
  File "C:\Users\abhishek.2.kumar\AppData\Local\Programs\Python\Python310\lib\ssl.py", line 1342, in do_handshake
    self._sslobj.do_handshake()
ssl.SSLCertVerificationError: [SSL: CERTIFICATE_VERIFY_FAILED] certificate verify failed: unable to get local issuer certificate (_ssl.c:997)

During handling of the above exception, another exception occurred:

Traceback (most recent call last):
  File "C:\Users\abhishek.2.kumar\course\venv\lib\site-packages\urllib3\connectionpool.py", line 787, in urlopen
    response = self._make_request(
  File "C:\Users\abhishek.2.kumar\course\venv\lib\site-packages\urllib3\connectionpool.py", line 488, in _make_request
    raise new_e
urllib3.exceptions.SSLError: [SSL: CERTIFICATE_VERIFY_FAILED] certificate verify failed: unable to get local issuer certificate (_ssl.c:997)

The above exception was the direct cause of the following exception:

Traceback (most recent call last):
  File "C:\Users\abhishek.2.kumar\course\venv\lib\site-packages\requests\adapters.py", line 667, in send
    resp = conn.urlopen(
  File "C:\Users\abhishek.2.kumar\course\venv\lib\site-packages\urllib3\connectionpool.py", line 841, in urlopen
    retries = retries.increment(
  File "C:\Users\abhishek.2.kumar\course\venv\lib\site-packages\urllib3\util\retry.py", line 519, in increment
    raise MaxRetryError(_pool, url, reason) from reason  # type: ignore[arg-type]
urllib3.exceptions.MaxRetryError: HTTPSConnectionPool(host='hub.getdbt.com', port=443): Max retries exceeded with url: /api/v1/index.json (Caused by SSLError(SSLCertVerificationError(1, '[SSL: CERTIFICATE_VERIFY_FAILED] certificate verify failed: unable to get local issuer certificate (_ssl.c:997)')))

During handling of the above exception, another exception occurred:

Traceback (most recent call last):
  File "C:\Users\abhishek.2.kumar\course\venv\lib\site-packages\dbt_common\utils\connection.py", line 21, in connection_exception_retry
    return fn()
  File "C:\Users\abhishek.2.kumar\course\venv\lib\site-packages\dbt\clients\registry.py", line 168, in _get_index
    resp = requests.get(url, timeout=30)
  File "C:\Users\abhishek.2.kumar\course\venv\lib\site-packages\requests\api.py", line 73, in get
    return request("get", url, params=params, **kwargs)
  File "C:\Users\abhishek.2.kumar\course\venv\lib\site-packages\requests\api.py", line 59, in request
    return session.request(method=method, url=url, **kwargs)
  File "C:\Users\abhishek.2.kumar\course\venv\lib\site-packages\requests\sessions.py", line 589, in request
    resp = self.send(prep, **send_kwargs)
  File "C:\Users\abhishek.2.kumar\course\venv\lib\site-packages\requests\sessions.py", line 703, in send
    r = adapter.send(request, **kwargs)
  File "C:\Users\abhishek.2.kumar\course\venv\lib\site-packages\requests\adapters.py", line 698, in send
    raise SSLError(e, request=request)
requests.exceptions.SSLError: HTTPSConnectionPool(host='hub.getdbt.com', port=443): Max retries exceeded with url: /api/v1/index.json (Caused by SSLError(SSLCertVerificationError(1, '[SSL: CERTIFICATE_VERIFY_FAILED] certificate verify failed: unable to get local issuer certificate (_ssl.c:997)')))

During handling of the above exception, another exception occurred:

Traceback (most recent call last):
  File "C:\Users\abhishek.2.kumar\course\venv\lib\site-packages\dbt\cli\requires.py", line 153, in wrapper
    result, success = func(*args, **kwargs)
  File "C:\Users\abhishek.2.kumar\course\venv\lib\site-packages\dbt\cli\requires.py", line 103, in wrapper
    return func(*args, **kwargs)
  File "C:\Users\abhishek.2.kumar\course\venv\lib\site-packages\dbt\cli\requires.py", line 218, in wrapper
    return func(*args, **kwargs)
  File "C:\Users\abhishek.2.kumar\course\venv\lib\site-packages\dbt\cli\requires.py", line 264, in wrapper
    return func(*args, **kwargs)
  File "C:\Users\abhishek.2.kumar\course\venv\lib\site-packages\dbt\cli\main.py", line 455, in deps
    results = task.run()
  File "C:\Users\abhishek.2.kumar\course\venv\lib\site-packages\dbt\task\deps.py", line 211, in run
    self.lock()
  File "C:\Users\abhishek.2.kumar\course\venv\lib\site-packages\dbt\task\deps.py", line 187, in lock
    resolved_deps = resolve_packages(packages, self.project, self.cli_vars)
  File "C:\Users\abhishek.2.kumar\course\venv\lib\site-packages\dbt\deps\resolver.py", line 131, in resolve_packages
    target = final[package].resolved().fetch_metadata(project, renderer)
  File "C:\Users\abhishek.2.kumar\course\venv\lib\site-packages\dbt\deps\registry.py", line 98, in resolved
    self._check_in_index()
  File "C:\Users\abhishek.2.kumar\course\venv\lib\site-packages\dbt\deps\registry.py", line 75, in _check_in_index
    index = registry.index_cached()
  File "C:\Users\abhishek.2.kumar\course\venv\lib\site-packages\dbt\utils.py", line 127, in __call__
    value = self.func(*args)
  File "C:\Users\abhishek.2.kumar\course\venv\lib\site-packages\dbt\clients\registry.py", line 189, in index
    return connection_exception_retry(get_index_fn, 5)
  File "C:\Users\abhishek.2.kumar\course\venv\lib\site-packages\dbt_common\utils\connection.py", line 34, in connection_exception_retry
    return connection_exception_retry(fn, max_attempts, attempt + 1)
  File "C:\Users\abhishek.2.kumar\course\venv\lib\site-packages\dbt_common\utils\connection.py", line 34, in connection_exception_retry
    return connection_exception_retry(fn, max_attempts, attempt + 1)
  File "C:\Users\abhishek.2.kumar\course\venv\lib\site-packages\dbt_common\utils\connection.py", line 34, in connection_exception_retry
    return connection_exception_retry(fn, max_attempts, attempt + 1)
  [Previous line repeated 2 more times]
  File "C:\Users\abhishek.2.kumar\course\venv\lib\site-packages\dbt_common\utils\connection.py", line 36, in connection_exception_retry
    raise ConnectionError("External connection exception occurred: " + str(exc))
dbt_common.exceptions.connection.ConnectionError: External connection exception occurred: HTTPSConnectionPool(host='hub.getdbt.com', port=443): Max retries exceeded with url: /api/v1/index.json (Caused by SSLError(SSLCertVerificationError(1, '[SSL: CERTIFICATE_VERIFY_FAILED] certificate verify failed: unable to get local issuer certificate (_ssl.c:997)')))

[0m17:19:02.886633 [debug] [MainThread]: Command `dbt deps` failed at 17:19:02.886633 after 7.87 seconds
[0m17:19:02.888188 [debug] [MainThread]: Sending event: {'category': 'dbt', 'action': 'invocation', 'label': 'end', 'context': [<snowplow_tracker.self_describing_json.SelfDescribingJson object at 0x000002BC9EA14A90>, <snowplow_tracker.self_describing_json.SelfDescribingJson object at 0x000002BC9DD41C90>, <snowplow_tracker.self_describing_json.SelfDescribingJson object at 0x000002BC9DD41CC0>]}
[0m17:19:02.889050 [debug] [MainThread]: Flushing usage events
[0m17:19:03.214484 [debug] [MainThread]: An error was encountered while trying to flush usage events
[0m17:32:53.508578 [debug] [MainThread]: Sending event: {'category': 'dbt', 'action': 'invocation', 'label': 'start', 'context': [<snowplow_tracker.self_describing_json.SelfDescribingJson object at 0x000001CF1A194A00>, <snowplow_tracker.self_describing_json.SelfDescribingJson object at 0x000001CF1C064880>, <snowplow_tracker.self_describing_json.SelfDescribingJson object at 0x000001CF1C064A90>]}


============================== 17:32:53.514670 | 5504cc48-b86c-46c0-835c-c4c25d7f8257 ==============================
[0m17:32:53.514670 [info ] [MainThread]: Running with dbt=1.9.1
[0m17:32:53.515600 [debug] [MainThread]: running dbt with arguments {'printer_width': '80', 'indirect_selection': 'eager', 'log_cache_events': 'False', 'write_json': 'True', 'partial_parse': 'True', 'cache_selected_only': 'False', 'profiles_dir': 'C:\\Users\\abhishek.2.kumar\\course\\dbt_demo', 'debug': 'False', 'version_check': 'True', 'log_path': 'C:\\Users\\abhishek.2.kumar\\course\\dbt_demo\\logs', 'fail_fast': 'False', 'warn_error': 'None', 'use_colors': 'True', 'use_experimental_parser': 'False', 'no_print': 'None', 'quiet': 'False', 'empty': 'None', 'log_format': 'default', 'static_parser': 'True', 'invocation_command': 'dbt clean', 'introspect': 'True', 'target_path': 'None', 'warn_error_options': 'WarnErrorOptions(include=[], exclude=[])', 'send_anonymous_usage_stats': 'True'}
[0m17:32:53.734193 [debug] [MainThread]: Sending event: {'category': 'dbt', 'action': 'project_id', 'label': '5504cc48-b86c-46c0-835c-c4c25d7f8257', 'context': [<snowplow_tracker.self_describing_json.SelfDescribingJson object at 0x000001CF1C06B0D0>]}
[0m17:32:53.762439 [debug] [MainThread]: Command `dbt clean` succeeded at 17:32:53.762439 after 0.39 seconds
[0m17:32:53.763439 [debug] [MainThread]: Sending event: {'category': 'dbt', 'action': 'invocation', 'label': 'end', 'context': [<snowplow_tracker.self_describing_json.SelfDescribingJson object at 0x000001CF1A194A00>, <snowplow_tracker.self_describing_json.SelfDescribingJson object at 0x000001CF1C068F70>, <snowplow_tracker.self_describing_json.SelfDescribingJson object at 0x000001CF1C069390>]}
[0m17:32:53.763439 [debug] [MainThread]: Flushing usage events
[0m17:32:54.196475 [debug] [MainThread]: An error was encountered while trying to flush usage events
